Workbook

Sheet Notes
A1: Notes on this run:
A3: Includes DXE dilution samples, Sunapee, and May-December reservoir samples.
B4: NOTE: DXE samples with visible algae need to be rerun.
A5: Bolded columns in QAQC have edited formulas from normal.
A6: Applied end of run curve to everything from S40 to the end, because checks aren't coming out correctly post-restarting the lachat.

Sheet QAQC
A1: Detection Date | B1: Detection Time | C1: Run File Name | D1: Sample ID | E1: Cup Number | F1: Sample Type | G1: Auto Dilution Factor | H1: Manual Dilution Factor | I1: Analyte Name | J1: Concentration Units | K1: Peak Height | L1: Peak Area | M1: Peak Concentration | N1: Analyte Name | O1: Concentration Units | P1: Peak Height | Q1: Peak Area | R1: Peak Concentration | S1: Column efficiency | T1: DILUTION FACTOR | U1: Analyst QUALITY CODE PO4-P: | V1: Analyst NOTES: | W1: PO4-P-- determined concentration | X1: PO4-P-- revised calibration | Y1: PO4-P-- dilution corrected | Z1: PO4-P- % Error in check stds | AA1: PO4-P- DQO (<=20%) | AB1: PO4-P- RPD of duplicates | AC1: PO4-P- DQO (<=20% if conc>LOQ) | AD1: PO4-P- PR of spikes | AE1: PO4-P- DQO (80-120%) if conc>LOQ | AF1: Analyst QUALITY CODE NO3-N: | AG1: Analyst NOTES: | AH1: NO3-N-- determined concentration | AI1: NO3-N-- revised calibration | AJ1: NO3-N-- dilution corrected | AK1: NO3-N- % Error in check stds | AL1: NO3-N- DQO (<=20%) | AM1: NO3-N- RPD of duplicates | AN1: NO3-N- DQO (<=20% if conc>LOQ) | AO1: NO3-N- PR of spikes | AP1: NO3-N- DQO (80-120%) if conc>LOQ | AR1: original order
A2: STANDARDS:
A3: 46085 | B3: 0.43225694 | C3: OM_3-4-2026_10-18-36AM.OMN | D3: dye | E3: S16 | F3: Unknown | G3: 1 | H3: 1 | I3: TP | J3: ug P/L | K3: 0.172 | L3: 1.79 | M3: 34.2 | N3: TN | O3: ug N/L | P3: -0.0107 | Q3: -0.121 | R3: -116 | T3: 1 | U3: 1 | W3: =M3*H3 -> 34.2 | X3: =W3 -> 34.2 | Y3: =IF(T3=1,X3,(X3*T3)) -> 34.2 | AF3: 1 | AH3: =R3*H3 -> -116 | AI3: =AH3 -> -116 | AJ3: =IF(T3=1,AI3,(AI3*T3)) -> -116 | AR3: 1
A4: 46085 | B4: 0.43318287 | C4: OM_3-4-2026_10-18-36AM.OMN | D4: dye | E4: S16 | F4: Unknown | G4: 1 | H4: 1 | I4: TP | J4: ug P/L | K4: 0.135 | L4: 1.37 | M4: 21.6 | N4: TN | O4: ug N/L | P4: 0.0251 | Q4: 0.0326 | R4: -100 | T4: 1 | U4: 1 | W4: =M4*H4 -> 21.6 | X4: =W4 -> 21.6 | Y4: =IF(T4=1,X4,(X4*T4)) -> 21.6 | AF4: 1 | AH4: =R4*H4 -> -100 | AI4: =AH4 -> -100 | AJ4: =IF(T4=1,AI4,(AI4*T4)) -> -100 | AR4: 2
A5: 46085 | B5: 0.43407407 | C5: OM_3-4-2026_10-18-36AM.OMN | D5: NO2 | E5: S1 | F5: Unknown | G5: 1 | H5: 1 | I5: TP | J5: ug P/L | K5: 0.14 | L5: 1.41 | M5: 22.8 | N5: TN | O5: ug N/L | P5: 1.89 | Q5: 20.6 | R5: 2030 | S5: =100*(Q6/Q5) -> 99.514563 | T5: 1 | U5: 1 | W5: =M5*H5 -> 22.8 | X5: =W5 -> 22.8 | Y5: =IF(T5=1,X5,(X5*T5)) -> 22.8 | AF5: 1 | AH5: =R5*H5 -> 2030 | AI5: =AH5 -> 2030 | AJ5: =IF(T5=1,AI5,(AI5*T5)) -> 2030 | AR5: 3
A6: 46085 | B6: 0.4349537 | C6: OM_3-4-2026_10-18-36AM.OMN | D6: NO3 | E6: S2 | F6: Unknown | G6: 1 | H6: 1 | I6: TP | J6: ug P/L | K6: 0.139 | L6: 1.39 | M6: 22.1 | N6: TN | O6: ug N/L | P6: 1.92 | Q6: 20.5 | R6: 2030 | T6: 1 | U6: 1 | W6: =M6*H6 -> 22.1 | X6: =W6 -> 22.1 | Y6: =IF(T6=1,X6,(X6*T6)) -> 22.1 | AF6: 1 | AH6: =R6*H6 -> 2030 | AI6: =AH6 -> 2030 | AJ6: =IF(T6=1,AI6,(AI6*T6)) -> 2030 | AR6: 4
A7: 46085 | B7: 0.43583333 | C7: OM_3-4-2026_10-18-36AM.OMN | D7: NO2 | E7: S1 | F7: Unknown | G7: 1 | H7: 1 | I7: TP | J7: ug P/L | K7: 0.138 | L7: 1.4 | M7: 22.6 | N7: TN | O7: ug N/L | P7: 1.83 | Q7: 20 | R7: 1970 | S7: =100*(Q8/Q7) -> 105.5 | T7: 1 | U7: 1 | W7: =M7*H7 -> 22.6 | X7: =W7 -> 22.6 | Y7: =IF(T7=1,X7,(X7*T7)) -> 22.6 | AF7: 1 | AH7: =R7*H7 -> 1970 | AI7: =AH7 -> 1970 | AJ7: =IF(T7=1,AI7,(AI7*T7)) -> 1970 | AR7: 5
A8: 46085 | B8: 0.43671296 | C8: OM_3-4-2026_10-18-36AM.OMN | D8: NO3 | E8: S2 | F8: Unknown | G8: 1 | H8: 1 | I8: TP | J8: ug P/L | K8: 0.143 | L8: 1.49 | M8: 25.1 | N8: TN | O8: ug N/L | P8: 1.98 | Q8: 21.1 | R8: 2090 | T8: 1 | U8: 1 | W8: =M8*H8 -> 25.1 | X8: =W8 -> 25.1 | Y8: =IF(T8=1,X8,(X8*T8)) -> 25.1 | AF8: 1 | AH8: =R8*H8 -> 2090 | AI8: =AH8 -> 2090 | AJ8: =IF(T8=1,AI8,(AI8*T8)) -> 2090 | AR8: 6
A9: 46085 | B9: 0.43760417 | C9: OM_3-4-2026_10-18-36AM.OMN | D9: water | E9: S3 | F9: Unknown | G9: 1 | H9: 1 | I9: TP | J9: ug P/L | K9: 0.141 | L9: 1.43 | M9: 23.2 | N9: TN | O9: ug N/L | P9: 0.0112 | Q9: 0.355 | R9: -66 | T9: 1 | U9: 1 | W9: =M9*H9 -> 23.2 | X9: =W9 -> 23.2 | Y9: =IF(T9=1,X9,(X9*T9)) -> 23.2 | AF9: 1 | AH9: =R9*H9 -> -66 | AI9: =AH9 -> -66 | AJ9: =IF(T9=1,AI9,(AI9*T9)) -> -66 | AR9: 7
A10: 46085 | B10: 0.43849537 | C10: OM_3-4-2026_10-18-36AM.OMN | D10: water | E10: S3 | F10: Unknown | G10: 1 | H10: 1 | I10: TP | J10: ug P/L | K10: 0.141 | L10: 1.46 | M10: 24.4 | N10: TN | O10: ug N/L | P10: 0.0306 | Q10: 0.052 | R10: -98 | T10: 1 | U10: 1 | W10: =M10*H10 -> 24.4 | X10: =W10 -> 24.4 | Y10: =IF(T10=1,X10,(X10*T10)) -> 24.4 | AF10: 1 | AH10: =R10*H10 -> -98 | AI10: =AH10 -> -98 | AJ10: =IF(T10=1,AI10,(AI10*T10)) -> -98 | AR10: 8
A11: 46085 | B11: 0.43939815 | C11: OM_3-4-2026_10-18-36AM.OMN | D11: bisulfate carrier | E11: S4 | F11: Unknown | G11: 1 | H11: 1 | I11: TP | J11: ug P/L | K11: 0.0104 | L11: 0.0978 | M11: -16.9 | N11: TN | O11: ug N/L | P11: -0.028 | Q11: -0.178 | R11: -122 | T11: 1 | U11: 1 | W11: =M11*H11 -> -16.9 | X11: =W11 -> -16.9 | Y11: =IF(T11=1,X11,(X11*T11)) -> -16.9 | AF11: 1 | AH11: =R11*H11 -> -122 | AI11: =AH11 -> -122 | AJ11: =IF(T11=1,AI11,(AI11*T11)) -> -122 | AR11: 9
A12: 46085 | B12: 0.44027778 | C12: OM_3-4-2026_10-18-36AM.OMN | D12: bisulfate carrier | E12: S4 | F12: Unknown | G12: 1 | H12: 1 | I12: TP | J12: ug P/L | K12: 0.0113 | L12: 0.11 | M12: -16.6 | N12: TN | O12: ug N/L | P12: -0.0216 | Q12: -0.165 | R12: -121 | T12: 1 | U12: 1 | W12: =M12*H12 -> -16.6 | X12: =W12 -> -16.6 | Y12: =IF(T12=1,X12,(X12*T12)) -> -16.6 | AF12: 1 | AH12: =R12*H12 -> -121 | AI12: =AH12 -> -121 | AJ12: =IF(T12=1,AI12,(AI12*T12)) -> -121 | AR12: 10
A13: 46085 | B13: 0.44118056 | C13: OM_3-4-2026_10-18-36AM.OMN | D13: cal std 150 | E13: 1 | F13: Calibration Standard | G13: 1 | H13: 1 | I13: TP | J13: ug P/L | K13: 0.294 | L13: 4.73 | M13: 150 | N13: TN | O13: ug N/L | P13: 1.93 | Q13: 20.2 | R13: 1500 | T13: 1 | U13: 1 | W13: =M13*H13 -> 150 | X13: =W13 -> 150 | Y13: =IF(T13=1,X13,(X13*T13)) -> 150 | AF13: 1 | AH13: =R13*H13 -> 1500 | AI13: =AH13 -> 1500 | AJ13: =IF(T13=1,AI13,(AI13*T13)) -> 1500 | AR13: 11
A14: 46085 | B14: 0.44208333 | C14: OM_3-4-2026_10-18-36AM.OMN | D14: cal std 150 | E14: 1 | F14: Calibration Standard | G14: 1 | H14: 1 | I14: TP | J14: ug P/L | K14: 0.294 | L14: 4.68 | M14: 150 | N14: TN | O14: ug N/L | P14: 1.96 | Q14: 20.6 | R14: 1500 | T14: 1 | U14: 1 | W14: =M14*H14 -> 150 | X14: =W14 -> 150 | Y14: =IF(T14=1,X14,(X14*T14)) -> 150 | AF14: 1 | AH14: =R14*H14 -> 1500 | AI14: =AH14 -> 1500 | AJ14: =IF(T14=1,AI14,(AI14*T14)) -> 1500 | AR14: 12
A15: 46085 | B15: 0.44297454 | C15: OM_3-4-2026_10-18-36AM.OMN | D15: cal std 100 | E15: 3 | F15: Calibration Standard | G15: 1 | H15: 1 | I15: TP | J15: ug P/L | K15: 0.202 | L15: 3.3 | M15: 100 | N15: TN | O15: ug N/L | P15: 1.32 | Q15: 14 | R15: 1000 | T15: 1 | U15: 1 | W15: =M15*H15 -> 100 | X15: =W15 -> 100 | Y15: =IF(T15=1,X15,(X15*T15)) -> 100 | AF15: 1 | AH15: =R15*H15 -> 1000 | AI15: =AH15 -> 1000 | AJ15: =IF(T15=1,AI15,(AI15*T15)) -> 1000 | AR15: 13
A16: 46085 | B16: 0.44386574 | C16: OM_3-4-2026_10-18-36AM.OMN | D16: cal std 100 | E16: 3 | F16: Calibration Standard | G16: 1 | H16: 1 | I16: TP | J16: ug P/L | K16: 0.202 | L16: 3.32 | M16: 100 | N16: TN | O16: ug N/L | P16: 1.3 | Q16: 13.8 | R16: 1000 | T16: 1 | U16: 1 | W16: =M16*H16 -> 100 | X16: =W16 -> 100 | Y16: =IF(T16=1,X16,(X16*T16)) -> 100 | AF16: 1 | AH16: =R16*H16 -> 1000 | AI16: =AH16 -> 1000 | AJ16: =IF(T16=1,AI16,(AI16*T16)) -> 1000 | AR16: 14
A17: 46085 | B17: 0.44475694 | C17: OM_3-4-2026_10-18-36AM.OMN | D17: cal std 50 | E17: 5 | F17: Calibration Standard | G17: 1 | H17: 1 | I17: TP | J17: ug P/L | K17: 0.102 | L17: 1.79 | M17: 50 | N17: TN | O17: ug N/L | P17: 0.65 | Q17: 7.12 | R17: 500 | T17: 1 | U17: 1 | W17: =M17*H17 -> 50 | X17: =W17 -> 50 | Y17: =IF(T17=1,X17,(X17*T17)) -> 50 | AF17: 1 | AH17: =R17*H17 -> 500 | AI17: =AH17 -> 500 | AJ17: =IF(T17=1,AI17,(AI17*T17)) -> 500 | AR17: 15
A18: 46085 | B18: 0.44564815 | C18: OM_3-4-2026_10-18-36AM.OMN | D18: cal std 50 | E18: 5 | F18: Calibration Standard | G18: 1 | H18: 1 | I18: TP | J18: ug P/L | K18: 0.101 | L18: 1.83 | M18: 50 | N18: TN | O18: ug N/L | P18: 0.69 | Q18: 7.41 | R18: 500 | T18: 1 | U18: 1 | W18: =M18*H18 -> 50 | X18: =W18 -> 50 | Y18: =IF(T18=1,X18,(X18*T18)) -> 50 | AF18: 1 | AH18: =R18*H18 -> 500 | AI18: =AH18 -> 500 | AJ18: =IF(T18=1,AI18,(AI18*T18)) -> 500 | AR18: 16
A19: 46085 | B19: 0.44652778 | C19: OM_3-4-2026_10-18-36AM.OMN | D19: cal std 25 | E19: 7 | F19: Calibration Standard | G19: 1 | H19: 1 | I19: TP | J19: ug P/L | K19: 0.0541 | L19: 1.15 | M19: 25 | N19: TN | O19: ug N/L | P19: 0.388 | Q19: 4.24 | R19: 250 | T19: 1 | U19: 1 | W19: =M19*H19 -> 25 | X19: =W19 -> 25 | Y19: =IF(T19=1,X19,(X19*T19)) -> 25 | AF19: 1 | AH19: =R19*H19 -> 250 | AI19: =AH19 -> 250 | AJ19: =IF(T19=1,AI19,(AI19*T19)) -> 250 | AR19: 17
A20: 46085 | B20: 0.44741898 | C20: OM_3-4-2026_10-18-36AM.OMN | D20: cal std 25 | E20: 7 | F20: Calibration Standard | G20: 1 | H20: 1 | I20: TP | J20: ug P/L | K20: 0.0544 | L20: 1.11 | M20: 25 | N20: TN | O20: ug N/L | P20: 0.409 | Q20: 4.35 | R20: 250 | T20: 1 | U20: 1 | W20: =M20*H20 -> 25 | X20: =W20 -> 25 | Y20: =IF(T20=1,X20,(X20*T20)) -> 25 | AF20: 1 | AH20: =R20*H20 -> 250 | AI20: =AH20 -> 250 | AJ20: =IF(T20=1,AI20,(AI20*T20)) -> 250 | AR20: 18
A21: 46085 | B21: 0.44829861 | C21: OM_3-4-2026_10-18-36AM.OMN | D21: cal std 10 | E21: 9 | F21: Calibration Standard | G21: 1 | H21: 1 | I21: TP | J21: ug P/L | K21: 0.0301 | L21: 0.734 | M21: 10 | N21: TN | O21: ug N/L | P21: 0.211 | Q21: 2.38 | R21: 100 | T21: 1 | U21: 1 | W21: =M21*H21 -> 10 | X21: =W21 -> 10 | Y21: =IF(T21=1,X21,(X21*T21)) -> 10 | AF21: 1 | AH21: =R21*H21 -> 100 | AI21: =AH21 -> 100 | AJ21: =IF(T21=1,AI21,(AI21*T21)) -> 100 | AR21: 19
A22: 46085 | B22: 0.44918981 | C22: OM_3-4-2026_10-18-36AM.OMN | D22: cal std 10 | E22: 9 | F22: Calibration Standard | G22: 1 | H22: 1 | I22: TP | J22: ug P/L | K22: 0.0294 | L22: 0.741 | M22: 10 | N22: TN | O22: ug N/L | P22: 0.211 | Q22: 2.54 | R22: 100 | T22: 1 | U22: 1 | W22: =M22*H22 -> 10 | X22: =W22 -> 10 | Y22: =IF(T22=1,X22,(X22*T22)) -> 10 | AF22: 1 | AH22: =R22*H22 -> 100 | AI22: =AH22 -> 100 | AJ22: =IF(T22=1,AI22,(AI22*T22)) -> 100 | AR22: 20
A23: 46085 | B23: 0.45006944 | C23: OM_3-4-2026_10-18-36AM.OMN | D23: cal std 5 | E23: 11 | F23: Calibration Standard | G23: 1 | H23: 1 | I23: TP | J23: ug P/L | K23: 0.0275 | L23: 0.728 | M23: 5 | N23: TN | O23: ug N/L | P23: 0.155 | Q23: 1.8 | R23: 50 | T23: 1 | U23: 3 | V23: off- excluded from curve | W23: =M23*H23 -> 5 | X23: =W23 -> 5 | Y23: =IF(T23=1,X23,(X23*T23)) -> 5 | AF23: 1 | AH23: =R23*H23 -> 50 | AI23: =AH23 -> 50 | AJ23: =IF(T23=1,AI23,(AI23*T23)) -> 50 | AR23: 21
A24: 46085 | B24: 0.45096065 | C24: OM_3-4-2026_10-18-36AM.OMN | D24: cal std 5 | E24: 11 | F24: Calibration Standard | G24: 1 | H24: 1 | I24: TP | J24: ug P/L | K24: 0.0261 | L24: 0.654 | M24: 5 | N24: TN | O24: ug N/L | P24: 0.148 | Q24: 1.71 | R24: 50 | T24: 1 | U24: 3 | V24: off- excluded from curve | W24: =M24*H24 -> 5 | X24: =W24 -> 5 | Y24: =IF(T24=1,X24,(X24*T24)) -> 5 | AF24: 1 | AH24: =R24*H24 -> 50 | AI24: =AH24 -> 50 | AJ24: =IF(T24=1,AI24,(AI24*T24)) -> 50 | AR24: 22
A25: 46085 | B25: 0.45184028 | C25: OM_3-4-2026_10-18-36AM.OMN | D25: cal std 0 | E25: 13 | F25: Calibration Standard | G25: 1 | H25: 1 | I25: TP | J25: ug P/L | K25: 0.0186 | L25: 0.409 | M25: 0 | N25: TN | O25: ug N/L | P25: 0.0779 | Q25: 1.04 | R25: 0 | T25: 1 | U25: 1 | W25: =M25*H25 -> 0 | X25: =W25 -> 0 | Y25: =IF(T25=1,X25,(X25*T25)) -> 0 | AF25: 1 | AH25: =R25*H25 -> 0 | AI25: =AH25 -> 0 | AJ25: =IF(T25=1,AI25,(AI25*T25)) -> 0 | AR25: 23
A26: 46085 | B26: 0.45271991 | C26: OM_3-4-2026_10-18-36AM.OMN | D26: cal std 0 | E26: 13 | F26: Calibration Standard | G26: 1 | H26: 1 | I26: TP | J26: ug P/L | K26: 0.0182 | L26: 0.42 | M26: 0 | N26: TN | O26: ug N/L | P26: 0.0745 | Q26: 0.964 | R26: 0 | T26: 1 | U26: 1 | W26: =M26*H26 -> 0 | X26: =W26 -> 0 | Y26: =IF(T26=1,X26,(X26*T26)) -> 0 | AF26: 1 | AH26: =R26*H26 -> 0 | AI26: =AH26 -> 0 | AJ26: =IF(T26=1,AI26,(AI26*T26)) -> 0 | AR26: 24
A35: METHOD CHECKS: | AR35: 33
A36: 46085 | B36: 0.45358796 | C36: OM_3-4-2026_10-18-36AM.OMN | D36: NO2 | E36: S1 | F36: Unknown | G36: 1 | H36: 1 | I36: TP | J36: ug P/L | K36: 0.138 | L36: 1.38 | M36: 31.1 | N36: TN | O36: ug N/L | P36: 1.88 | Q36: 20.3 | R36: 1500 | S36: =100*(Q37/Q36) -> 100.49261 | T36: 1 | U36: 1 | W36: =M36*H36 -> 31.1 | X36: =W36 -> 31.1 | Y36: =IF(T36=1,X36,(X36*T36)) -> 31.1 | AF36: 1 | AH36: =R36*H36 -> 1500 | AI36: =AH36 -> 1500 | AJ36: =IF(T36=1,AI36,(AI36*T36)) -> 1500 | AR36: 34
A37: 46085 | B37: 0.45447917 | C37: OM_3-4-2026_10-18-36AM.OMN | D37: NO3 | E37: S2 | F37: Unknown | G37: 1 | H37: 1 | I37: TP | J37: ug P/L | K37: 0.141 | L37: 1.46 | M37: 34 | N37: TN | O37: ug N/L | P37: 1.92 | Q37: 20.4 | R37: 1510 | T37: 1 | U37: 1 | W37: =M37*H37 -> 34 | X37: =W37 -> 34 | Y37: =IF(T37=1,X37,(X37*T37)) -> 34 | AF37: 1 | AH37: =R37*H37 -> 1510 | AI37: =AH37 -> 1510 | AJ37: =IF(T37=1,AI37,(AI37*T37)) -> 1510 | AR37: 35
A38: 46085 | B38: 0.45537037 | C38: OM_3-4-2026_10-18-36AM.OMN | D38: water | E38: S3 | F38: Unknown | G38: 1 | H38: 1 | I38: TP | J38: ug P/L | K38: 0.137 | L38: 1.37 | M38: 31 | N38: TN | O38: ug N/L | P38: -0.00324 | Q38: -0.0198 | R38: -85 | T38: 1 | U38: 1 | W38: =M38*H38 -> 31 | X38: =W38 -> 31 | Y38: =IF(T38=1,X38,(X38*T38)) -> 31 | AF38: 1 | AH38: =R38*H38 -> -85 | AI38: =AH38 -> -85 | AJ38: =IF(T38=1,AI38,(AI38*T38)) -> -85 | AR38: 36
A39: 46085 | B39: 0.45626157 | C39: OM_3-4-2026_10-18-36AM.OMN | D39: water blank | E39: 19 | F39: Unknown | G39: 1 | H39: 1 | I39: TP | J39: ug P/L | K39: 0.0189 | L39: 0.41 | M39: -1.72 | N39: TN | O39: ug N/L | P39: 0.0752 | Q39: 0.971 | R39: -7.82 | T39: 1 | U39: 1 | W39: =M39*H39 -> -1.72 | X39: =W39 -> -1.72 | Y39: =IF(T39=1,X39,(X39*T39)) -> -1.72 | AF39: 1 | AH39: =R39*H39 -> -7.82 | AI39: =AH39 -> -7.82 | AJ39: =IF(T39=1,AI39,(AI39*T39)) -> -7.82 | AR39: 37
A40: 46085 | B40: 0.45715278 | C40: OM_3-4-2026_10-18-36AM.OMN | D40: water blank | E40: 20 | F40: Unknown | G40: 1 | H40: 1 | I40: TP | J40: ug P/L | K40: 0.0196 | L40: 0.395 | M40: -2.22 | N40: TN | O40: ug N/L | P40: 0.0883 | Q40: 1.12 | R40: 3.67 | T40: 1 | U40: 1 | W40: =M40*H40 -> -2.22 | X40: =W40 -> -2.22 | Y40: =IF(T40=1,X40,(X40*T40)) -> -2.22 | AF40: 1 | AH40: =R40*H40 -> 3.67 | AI40: =AH40 -> 3.67 | AJ40: =IF(T40=1,AI40,(AI40*T40)) -> 3.67 | AR40: 38
A41: 46085 | B41: 0.45804398 | C41: OM_3-4-2026_10-18-36AM.OMN | D41: water blank | E41: 21 | F41: Unknown | G41: 1 | H41: 1 | I41: TP | J41: ug P/L | K41: 0.0174 | L41: 0.415 | M41: -1.56 | N41: TN | O41: ug N/L | P41: 0.0736 | Q41: 0.978 | R41: -7.26 | T41: 1 | U41: 1 | W41: =M41*H41 -> -1.56 | X41: =W41 -> -1.56 | Y41: =IF(T41=1,X41,(X41*T41)) -> -1.56 | AF41: 1 | AH41: =R41*H41 -> -7.26 | AI41: =AH41 -> -7.26 | AJ41: =IF(T41=1,AI41,(AI41*T41)) -> -7.26 | AR41: 39
A42: 46085 | B42: 0.45893519 | C42: OM_3-4-2026_10-18-36AM.OMN | D42: water blank | E42: 22 | F42: Unknown | G42: 1 | H42: 1 | I42: TP | J42: ug P/L | K42: 0.0212 | L42: 0.486 | M42: 0.811 | N42: TN | O42: ug N/L | P42: 0.0751 | Q42: 0.944 | R42: -9.93 | T42: 1 | U42: 1 | W42: =M42*H42 -> 0.811 | X42: =W42 -> 0.811 | Y42: =IF(T42=1,X42,(X42*T42)) -> 0.811 | AF42: 1 | AH42: =R42*H42 -> -9.93 | AI42: =AH42 -> -9.93 | AJ42: =IF(T42=1,AI42,(AI42*T42)) -> -9.93 | AR42: 40
A43: 46085 | B43: 0.45981481 | C43: OM_3-4-2026_10-18-36AM.OMN | D43: water blank | E43: 23 | F43: Unknown | G43: 1 | H43: 1 | I43: TP | J43: ug P/L | K43: 0.0202 | L43: 0.446 | M43: -0.533 | N43: TN | O43: ug N/L | P43: 0.0798 | Q43: 1.12 | R43: 3.8 | T43: 1 | U43: 1 | W43: =M43*H43 -> -0.533 | X43: =W43 -> -0.533 | Y43: =IF(T43=1,X43,(X43*T43)) -> -0.533 | AF43: 1 | AH43: =R43*H43 -> 3.8 | AI43: =AH43 -> 3.8 | AJ43: =IF(T43=1,AI43,(AI43*T43)) -> 3.8 | AR43: 41
A44: 46085 | B44: 0.46069444 | C44: OM_3-4-2026_10-18-36AM.OMN | D44: digest check | E44: 24 | F44: Unknown | G44: 1 | H44: 1 | I44: TP | J44: ug P/L | K44: 0.0856 | L44: 1.64 | M44: 40.4 | N44: TN | O44: ug N/L | P44: 0.564 | Q44: 6.09 | R44: 391 | T44: 1 | U44: 1 | W44: =M44*H44 -> 40.4 | X44: =W44 -> 40.4 | Y44: =IF(T44=1,X44,(X44*T44)) -> 40.4 | AF44: 1 | AH44: =R44*H44 -> 391 | AI44: =AH44 -> 391 | AJ44: =IF(T44=1,AI44,(AI44*T44)) -> 391 | AR44: 42
A45: 46085 | B45: 0.46158565 | C45: OM_3-4-2026_10-18-36AM.OMN | D45: digest check | E45: 25 | F45: Unknown | G45: 1 | H45: 1 | I45: TP | J45: ug P/L | K45: 0.0858 | L45: 1.59 | M45: 38.5 | N45: TN | O45: ug N/L | P45: 0.586 | Q45: 6.32 | R45: 409 | T45: 1 | U45: 1 | W45: =M45*H45 -> 38.5 | X45: =W45 -> 38.5 | Y45: =IF(T45=1,X45,(X45*T45)) -> 38.5 | AF45: 1 | AH45: =R45*H45 -> 409 | AI45: =AH45 -> 409 | AJ45: =IF(T45=1,AI45,(AI45*T45)) -> 409 | AR45: 43
A46: 46085 | B46: 0.46246528 | C46: OM_3-4-2026_10-18-36AM.OMN | D46: digest check | E46: 26 | F46: Unknown | G46: 1 | H46: 1 | I46: TP | J46: ug P/L | K46: 0.0854 | L46: 1.62 | M46: 39.5 | N46: TN | O46: ug N/L | P46: 0.538 | Q46: 5.85 | R46: 372 | T46: 1 | U46: 1 | W46: =M46*H46 -> 39.5 | X46: =W46 -> 39.5 | Y46: =IF(T46=1,X46,(X46*T46)) -> 39.5 | AF46: 1 | AH46: =R46*H46 -> 372 | AI46: =AH46 -> 372 | AJ46: =IF(T46=1,AI46,(AI46*T46)) -> 372 | AR46: 44
A47: 46085 | B47: 0.46334491 | C47: OM_3-4-2026_10-18-36AM.OMN | D47: digest check | E47: 27 | F47: Unknown | G47: 1 | H47: 1 | I47: TP | J47: ug P/L | K47: 0.0824 | L47: 1.56 | M47: 37.5 | N47: TN | O47: ug N/L | P47: 0.557 | Q47: 6.13 | R47: 394 | T47: 1 | U47: 1 | W47: =M47*H47 -> 37.5 | X47: =W47 -> 37.5 | Y47: =IF(T47=1,X47,(X47*T47)) -> 37.5 | AF47: 1 | AH47: =R47*H47 -> 394 | AI47: =AH47 -> 394 | AJ47: =IF(T47=1,AI47,(AI47*T47)) -> 394 | AR47: 45
A48: 46085 | B48: 0.46422454 | C48: OM_3-4-2026_10-18-36AM.OMN | D48: digest check | E48: 28 | F48: Unknown | G48: 1 | H48: 1 | I48: TP | J48: ug P/L | K48: 0.0845 | L48: 1.67 | M48: 41.4 | N48: TN | O48: ug N/L | P48: 0.599 | Q48: 6.45 | R48: 418 | T48: 1 | U48: 1 | W48: =M48*H48 -> 41.4 | X48: =W48 -> 41.4 | Y48: =IF(T48=1,X48,(X48*T48)) -> 41.4 | AF48: 1 | AH48: =R48*H48 -> 418 | AI48: =AH48 -> 418 | AJ48: =IF(T48=1,AI48,(AI48*T48)) -> 418 | AR48: 46
...

Sheet method checks
A1: Detection Date | B1: Detection Time | C1: Run File Name | D1: Sample ID | E1: Cup Number | F1: Sample Type | G1: Auto Dilution Factor | H1: Manual Dilution Factor | I1: Analyte Name | J1: Concentration Units | K1: Peak Height | L1: Peak Area | M1: Peak Concentration | N1: Analyte Name | O1: Concentration Units | P1: Peak Height | Q1: Peak Area | R1: Peak Concentration | S1: Column efficiency | T1: DILUTION BY OXIDATION REAGENT | U1: Analyst QUALITY CODE PO4-P: | V1: Analyst NOTES: | W1: PO4-P-- determined concentration | X1: PO4-P-- blank corrected | Y1: PO4-P-- dilution corrected | Z1: PO4-P- % Error in check stds | AA1: PO4-P- DQO (<=20%) | AB1: PO4-P- RPD of duplicates | AC1: PO4-P- DQO (<=20% if conc>LOQ) | AD1: PO4-P- PR of spikes | AE1: PO4-P- DQO (80-120%) if conc>LOQ | AF1: Analyst QUALITY CODE NO3-N: | AG1: Analyst NOTES: | AH1: NO3-N-- determined concentration | AI1: NO3-N-- blank corrected | AJ1: NO3-N-- dilution corrected | AK1: NO3-N- % Error in check stds | AL1: NO3-N- DQO (<=20%) | AM1: NO3-N- RPD of duplicates | AN1: NO3-N- DQO (<=20% if conc>LOQ) | AO1: NO3-N- PR of spikes | AP1: NO3-N- DQO (80-120%) if conc>LOQ
A2: BLANKS-digested type I reagent grade water
A3: 46085 | B3: 0.45626157 | C3: OM_3-4-2026_10-18-36AM.OMN | D3: water blank | E3: 19 | F3: Unknown | G3: 1 | H3: 1 | I3: TP | J3: ug P/L | K3: 0.0189 | L3: 0.41 | M3: -1.72 | N3: TN | O3: ug N/L | P3: 0.0752 | Q3: 0.971 | R3: -7.82 | T3: 1 | U3: 1 | W3: -1.72 | X3: -1.72 | Y3: -1.72 | AF3: 1 | AH3: -7.82 | AI3: -7.82 | AJ3: -7.82 | AR3: 37
A4: 46085 | B4: 0.45715278 | C4: OM_3-4-2026_10-18-36AM.OMN | D4: water blank | E4: 20 | F4: Unknown | G4: 1 | H4: 1 | I4: TP | J4: ug P/L | K4: 0.0196 | L4: 0.395 | M4: -2.22 | N4: TN | O4: ug N/L | P4: 0.0883 | Q4: 1.12 | R4: 3.67 | T4: 1 | U4: 1 | W4: -2.22 | X4: -2.22 | Y4: -2.22 | AF4: 1 | AH4: 3.67 | AI4: 3.67 | AJ4: 3.67 | AR4: 38
A5: 46085 | B5: 0.45804398 | C5: OM_3-4-2026_10-18-36AM.OMN | D5: water blank | E5: 21 | F5: Unknown | G5: 1 | H5: 1 | I5: TP | J5: ug P/L | K5: 0.0174 | L5: 0.415 | M5: -1.56 | N5: TN | O5: ug N/L | P5: 0.0736 | Q5: 0.978 | R5: -7.26 | T5: 1 | U5: 1 | W5: -1.56 | X5: -1.56 | Y5: -1.56 | AF5: 1 | AH5: -7.26 | AI5: -7.26 | AJ5: -7.26 | AR5: 39
A6: 46085 | B6: 0.45893519 | C6: OM_3-4-2026_10-18-36AM.OMN | D6: water blank | E6: 22 | F6: Unknown | G6: 1 | H6: 1 | I6: TP | J6: ug P/L | K6: 0.0212 | L6: 0.486 | M6: 0.811 | N6: TN | O6: ug N/L | P6: 0.0751 | Q6: 0.944 | R6: -9.93 | T6: 1 | U6: 1 | W6: 0.811 | X6: 0.811 | Y6: 0.811 | AF6: 1 | AH6: -9.93 | AI6: -9.93 | AJ6: -9.93 | AR6: 40
A7: 46085 | B7: 0.45981481 | C7: OM_3-4-2026_10-18-36AM.OMN | D7: water blank | E7: 23 | F7: Unknown | G7: 1 | H7: 1 | I7: TP | J7: ug P/L | K7: 0.0202 | L7: 0.446 | M7: -0.533 | N7: TN | O7: ug N/L | P7: 0.0798 | Q7: 1.12 | R7: 3.8 | T7: 1 | U7: 1 | W7: -0.533 | X7: -0.533 | Y7: -0.533 | AF7: 1 | AH7: 3.8 | AI7: 3.8 | AJ7: 3.8 | AR7: 41
J11: Known Conc | M11: 0 | O11: Known Conc | R11: 0
J12: Mean | L12: =AVERAGE(L3:L7) -> 0.4304 | M12: =AVERAGE(M3:M7) -> -1.0444 | O12: Mean | Q12: =AVERAGE(Q3:Q7) -> 1.0266 | R12: =AVERAGE(R3:R7) -> -3.508
J13: Std Dev | L13: =_xlfn.STDEV.S(L3:L7) -> 0.036198066 | M13: =_xlfn.STDEV.S(M3:M7) -> 1.2050263 | O13: Std Dev | Q13: =_xlfn.STDEV.S(Q3:Q7) -> 0.086202088 | R13: =_xlfn.STDEV.S(R3:R7) -> 6.6866187
J14: CV or %RSD | L14: =100*L13/L12 -> 8.4103314 | M14: =100*M13/M12 -> -115.37976 | O14: CV or %RSD | Q14: =100*Q13/Q12 -> 8.3968525 | R14: =100*R13/R12 -> -190.61057
J15: T value | L15: =TINV(0.02,4) -> 3.7469474 | M15: =TINV(0.02,4) -> 3.7469474 | O15: T value | Q15: =TINV(0.02,4) -> 3.7469474 | R15: =TINV(0.02,4) -> 3.7469474
J16: MDL | L16: =L13*L15 -> 0.13563225 | M16: =M13*M15 -> 4.51517 | O16: MDL | Q16: =Q13*Q15 -> 0.32299469 | R16: =R13*R15 -> 25.054409
J17: LOQ | L17: =10*L13 -> 0.36198066 | M17: =10*M13 -> 12.050263 | O17: LOQ | Q17: =10*Q13 -> 0.86202088 | R17: =10*R13 -> 66.866187
J18: Error as % | O18: Error as %
J19: Known/MDL | O19: Known/MDL
J20: Mean PR | O20: Mean PR
J21: S/N | L21: =L12/L13 -> 11.890138 | M21: =M12/M13 -> -0.8667031 | O21: S/N | Q21: =Q12/Q13 -> 11.909224 | R21: =R12/R13 -> -0.52462988 | X21: MEANS | Y21: =AVERAGE(Y3:Y7) -> -1.0444 | AI21: MEANS | AJ21: =AVERAGE(AJ3:AJ7) -> -3.508
F22: Different from 0? | H22: one sample T-test | L22: p value | M22: 0.4149 | Q22: p value | R22: 0.3504
J23: count | L23: =COUNT(M3:M10) -> 5 | Q23: =COUNT(R3:R10) -> 5
J24: std error of mean | L24: =M13/SQRT(L23) -> 0.53890413 | Q24: =R13/SQRT(Q23) -> 2.9903468
J25: df | L25: =L23-1 -> 4 | Q25: =Q23-1 -> 4
J26: t | L26: =ABS((M12-0)/L24) -> 1.938007 | Q26: =ABS((R12-0)/Q24) -> 1.1731081
J27: p value | L27: =_xlfn.T.DIST.2T(L26,L25) -> 0.12466252 | Q27: =_xlfn.T.DIST.2T(Q26,Q25) -> 0.30584146
A29: DIGESTION CHECK - is organic material completely converted to inorganic?
A30: 46085 | B30: 0.46069444 | C30: OM_3-4-2026_10-18-36AM.OMN | D30: digest check | E30: 24 | F30: Unknown | G30: 1 | H30: 1 | I30: TP | J30: ug P/L | K30: 0.0856 | L30: 1.64 | M30: 40.4 | N30: TN | O30: ug N/L | P30: 0.564 | Q30: 6.09 | R30: 391 | T30: 1 | U30: 1 | W30: 40.4 | X30: 40.4 | Y30: 40.4 | AF30: 1 | AH30: 391 | AI30: 391 | AJ30: 391 | AR30: 42
A31: 46085 | B31: 0.46158565 | C31: OM_3-4-2026_10-18-36AM.OMN | D31: digest check | E31: 25 | F31: Unknown | G31: 1 | H31: 1 | I31: TP | J31: ug P/L | K31: 0.0858 | L31: 1.59 | M31: 38.5 | N31: TN | O31: ug N/L | P31: 0.586 | Q31: 6.32 | R31: 409 | T31: 1 | U31: 1 | W31: 38.5 | X31: 38.5 | Y31: 38.5 | AF31: 1 | AH31: 409 | AI31: 409 | AJ31: 409 | AR31: 43
A32: 46085 | B32: 0.46246528 | C32: OM_3-4-2026_10-18-36AM.OMN | D32: digest check | E32: 26 | F32: Unknown | G32: 1 | H32: 1 | I32: TP | J32: ug P/L | K32: 0.0854 | L32: 1.62 | M32: 39.5 | N32: TN | O32: ug N/L | P32: 0.538 | Q32: 5.85 | R32: 372 | T32: 1 | U32: 1 | W32: 39.5 | X32: 39.5 | Y32: 39.5 | AF32: 1 | AH32: 372 | AI32: 372 | AJ32: 372 | AR32: 44
A33: 46085 | B33: 0.46334491 | C33: OM_3-4-2026_10-18-36AM.OMN | D33: digest check | E33: 27 | F33: Unknown | G33: 1 | H33: 1 | I33: TP | J33: ug P/L | K33: 0.0824 | L33: 1.56 | M33: 37.5 | N33: TN | O33: ug N/L | P33: 0.557 | Q33: 6.13 | R33: 394 | T33: 1 | U33: 1 | W33: 37.5 | X33: 37.5 | Y33: 37.5 | AF33: 1 | AH33: 394 | AI33: 394 | AJ33: 394 | AR33: 45
A34: 46085 | B34: 0.46422454 | C34: OM_3-4-2026_10-18-36AM.OMN | D34: digest check | E34: 28 | F34: Unknown | G34: 1 | H34: 1 | I34: TP | J34: ug P/L | K34: 0.0845 | L34: 1.67 | M34: 41.4 | N34: TN | O34: ug N/L | P34: 0.599 | Q34: 6.45 | R34: 418 | T34: 1 | U34: 1 | W34: 41.4 | X34: 41.4 | Y34: 41.4 | AF34: 1 | AH34: 418 | AI34: 418 | AJ34: 418 | AR34: 46
L38: Known Conc | M38: 40 | Q38: Known Conc | R38: 400 | X38: Known Conc | Y38: 40 | AI38: Known Conc | AJ38: 400
L39: Mean | M39: =AVERAGE(M30:M34) -> 39.46 | Q39: Mean | R39: =AVERAGE(R30:R34) -> 396.8 | X39: Mean | Y39: =AVERAGE(Y30:Y34) -> 39.46 | AI39: Mean | AJ39: =AVERAGE(AJ30:AJ34) -> 396.8
L40: Std Dev | M40: =_xlfn.STDEV.S(M30:M34) -> 1.5339492 | Q40: Std Dev | R40: =_xlfn.STDEV.S(R30:R34) -> 17.711578 | X40: Std Dev | Y40: =_xlfn.STDEV.S(Y30:Y34) -> 1.5339492 | AI40: Std Dev | AJ40: =_xlfn.STDEV.S(AJ30:AJ34) -> 17.711578
L41: CV or %RSD | M41: =100*M40/M39 -> 3.8873521 | Q41: CV or %RSD | R41: =100*R40/R39 -> 4.4636034 | X41: CV or %RSD | Y41: =100*Y40/Y39 -> 3.8873521 | AI41: CV or %RSD | AJ41: =100*AJ40/AJ39 -> 4.4636034
L42: T value | M42: =TINV(0.02,4) -> 3.7469474 | Q42: T value | R42: =TINV(0.02,4) -> 3.7469474 | X42: T value | Y42: =TINV(0.02,4) -> 3.7469474 | AI42: T value | AJ42: =TINV(0.02,4) -> 3.7469474
L43: MDL | M43: =M40*M42 -> 5.7476268 | Q43: MDL | R43: =R40*R42 -> 66.364351 | X43: MDL | Y43: =Y40*Y42 -> 5.7476268 | AI43: MDL | AJ43: =AJ40*AJ42 -> 66.364351
L44: LOQ | M44: =10*M40 -> 15.339492 | Q44: LOQ | R44: =10*R40 -> 177.11578 | X44: LOQ | Y44: =10*Y40 -> 15.339492 | AI44: LOQ | AJ44: =10*AJ40 -> 177.11578
L45: Error as % | M45: =100*(M39-M38)/M38 -> -1.35 | Q45: Error as % | R45: =100*(R39-R38)/R38 -> -0.8 | X45: Error as % | Y45: =100*(Y39-Y38)/Y38 -> -1.35 | AI45: Error as % | AJ45: =100*(AJ39-AJ38)/AJ38 -> -0.8
L46: Known/MDL | Q46: Known/MDL | X46: Known/MDL | AI46: Known/MDL
L47: Mean PR | M47: =100*M39/M38 -> 98.65 | Q47: Mean PR | R47: =100*R39/R38 -> 99.2 | X47: Mean PR | AI47: Mean PR
...

Sheet Raw Data
A1: Detection Date | B1: Detection Time | C1: Run File Name | D1: Sample ID | E1: Sample Name | F1: Cup Number | G1: Sample Type | H1: Auto Dilution Factor | I1: Manual Dilution Factor | J1: Analyte Name | K1: Concentration Units | L1: Peak Height | M1: Peak Area | N1: Peak Concentration | O1: Analyte Name | P1: Concentration Units | Q1: Peak Height | R1: Peak Area | S1: Peak Concentration
A3: 46085 | B3: 0.43225694 | C3: OM_3-4-2026_10-18-36AM.OMN | D3: dye | F3: S16 | G3: Unknown | H3: 1 | I3: 1 | J3: TP | K3: ug P/L | L3: 0.172 | M3: 1.79 | N3: 34.2 | O3: TN | P3: ug N/L | Q3: -0.0107 | R3: -0.121 | S3: -116
A4: 46085 | B4: 0.43318287 | C4: OM_3-4-2026_10-18-36AM.OMN | D4: dye | F4: S16 | G4: Unknown | H4: 1 | I4: 1 | J4: TP | K4: ug P/L | L4: 0.135 | M4: 1.37 | N4: 21.6 | O4: TN | P4: ug N/L | Q4: 0.0251 | R4: 0.0326 | S4: -100
A5: 46085 | B5: 0.43407407 | C5: OM_3-4-2026_10-18-36AM.OMN | D5: NO2 | F5: S1 | G5: Unknown | H5: 1 | I5: 1 | J5: TP | K5: ug P/L | L5: 0.14 | M5: 1.41 | N5: 22.8 | O5: TN | P5: ug N/L | Q5: 1.89 | R5: 20.6 | S5: 2030
A6: 46085 | B6: 0.4349537 | C6: OM_3-4-2026_10-18-36AM.OMN | D6: NO3 | F6: S2 | G6: Unknown | H6: 1 | I6: 1 | J6: TP | K6: ug P/L | L6: 0.139 | M6: 1.39 | N6: 22.1 | O6: TN | P6: ug N/L | Q6: 1.92 | R6: 20.5 | S6: 2030
A7: 46085 | B7: 0.43583333 | C7: OM_3-4-2026_10-18-36AM.OMN | D7: NO2 | F7: S1 | G7: Unknown | H7: 1 | I7: 1 | J7: TP | K7: ug P/L | L7: 0.138 | M7: 1.4 | N7: 22.6 | O7: TN | P7: ug N/L | Q7: 1.83 | R7: 20 | S7: 1970
A8: 46085 | B8: 0.43671296 | C8: OM_3-4-2026_10-18-36AM.OMN | D8: NO3 | F8: S2 | G8: Unknown | H8: 1 | I8: 1 | J8: TP | K8: ug P/L | L8: 0.143 | M8: 1.49 | N8: 25.1 | O8: TN | P8: ug N/L | Q8: 1.98 | R8: 21.1 | S8: 2090
A9: 46085 | B9: 0.43760417 | C9: OM_3-4-2026_10-18-36AM.OMN | D9: water | F9: S3 | G9: Unknown | H9: 1 | I9: 1 | J9: TP | K9: ug P/L | L9: 0.141 | M9: 1.43 | N9: 23.2 | O9: TN | P9: ug N/L | Q9: 0.0112 | R9: 0.355 | S9: -66
A10: 46085 | B10: 0.43849537 | C10: OM_3-4-2026_10-18-36AM.OMN | D10: water | F10: S3 | G10: Unknown | H10: 1 | I10: 1 | J10: TP | K10: ug P/L | L10: 0.141 | M10: 1.46 | N10: 24.4 | O10: TN | P10: ug N/L | Q10: 0.0306 | R10: 0.052 | S10: -98
A11: 46085 | B11: 0.43939815 | C11: OM_3-4-2026_10-18-36AM.OMN | D11: bisulfate carrier | F11: S4 | G11: Unknown | H11: 1 | I11: 1 | J11: TP | K11: ug P/L | L11: 0.0104 | M11: 0.0978 | N11: -16.9 | O11: TN | P11: ug N/L | Q11: -0.028 | R11: -0.178 | S11: -122
A12: 46085 | B12: 0.44027778 | C12: OM_3-4-2026_10-18-36AM.OMN | D12: bisulfate carrier | F12: S4 | G12: Unknown | H12: 1 | I12: 1 | J12: TP | K12: ug P/L | L12: 0.0113 | M12: 0.11 | N12: -16.6 | O12: TN | P12: ug N/L | Q12: -0.0216 | R12: -0.165 | S12: -121
A13: 46085 | B13: 0.44118056 | C13: OM_3-4-2026_10-18-36AM.OMN | D13: cal std 150 | F13: 1 | G13: Calibration Standard | H13: 1 | I13: 1 | J13: TP | K13: ug P/L | L13: 0.294 | M13: 4.73 | N13: 150 | O13: TN | P13: ug N/L | Q13: 1.93 | R13: 20.2 | S13: 1500
A14: 46085 | B14: 0.44208333 | C14: OM_3-4-2026_10-18-36AM.OMN | D14: cal std 150 | F14: 1 | G14: Calibration Standard | H14: 1 | I14: 1 | J14: TP | K14: ug P/L | L14: 0.294 | M14: 4.68 | N14: 150 | O14: TN | P14: ug N/L | Q14: 1.96 | R14: 20.6 | S14: 1500
A15: 46085 | B15: 0.44297454 | C15: OM_3-4-2026_10-18-36AM.OMN | D15: cal std 100 | F15: 3 | G15: Calibration Standard | H15: 1 | I15: 1 | J15: TP | K15: ug P/L | L15: 0.202 | M15: 3.3 | N15: 100 | O15: TN | P15: ug N/L | Q15: 1.32 | R15: 14 | S15: 1000
A16: 46085 | B16: 0.44386574 | C16: OM_3-4-2026_10-18-36AM.OMN | D16: cal std 100 | F16: 3 | G16: Calibration Standard | H16: 1 | I16: 1 | J16: TP | K16: ug P/L | L16: 0.202 | M16: 3.32 | N16: 100 | O16: TN | P16: ug N/L | Q16: 1.3 | R16: 13.8 | S16: 1000
A17: 46085 | B17: 0.44475694 | C17: OM_3-4-2026_10-18-36AM.OMN | D17: cal std 50 | F17: 5 | G17: Calibration Standard | H17: 1 | I17: 1 | J17: TP | K17: ug P/L | L17: 0.102 | M17: 1.79 | N17: 50 | O17: TN | P17: ug N/L | Q17: 0.65 | R17: 7.12 | S17: 500
A18: 46085 | B18: 0.44564815 | C18: OM_3-4-2026_10-18-36AM.OMN | D18: cal std 50 | F18: 5 | G18: Calibration Standard | H18: 1 | I18: 1 | J18: TP | K18: ug P/L | L18: 0.101 | M18: 1.83 | N18: 50 | O18: TN | P18: ug N/L | Q18: 0.69 | R18: 7.41 | S18: 500
A19: 46085 | B19: 0.44652778 | C19: OM_3-4-2026_10-18-36AM.OMN | D19: cal std 25 | F19: 7 | G19: Calibration Standard | H19: 1 | I19: 1 | J19: TP | K19: ug P/L | L19: 0.0541 | M19: 1.15 | N19: 25 | O19: TN | P19: ug N/L | Q19: 0.388 | R19: 4.24 | S19: 250
A20: 46085 | B20: 0.44741898 | C20: OM_3-4-2026_10-18-36AM.OMN | D20: cal std 25 | F20: 7 | G20: Calibration Standard | H20: 1 | I20: 1 | J20: TP | K20: ug P/L | L20: 0.0544 | M20: 1.11 | N20: 25 | O20: TN | P20: ug N/L | Q20: 0.409 | R20: 4.35 | S20: 250
A21: 46085 | B21: 0.44829861 | C21: OM_3-4-2026_10-18-36AM.OMN | D21: cal std 10 | F21: 9 | G21: Calibration Standard | H21: 1 | I21: 1 | J21: TP | K21: ug P/L | L21: 0.0301 | M21: 0.734 | N21: 10 | O21: TN | P21: ug N/L | Q21: 0.211 | R21: 2.38 | S21: 100
A22: 46085 | B22: 0.44918981 | C22: OM_3-4-2026_10-18-36AM.OMN | D22: cal std 10 | F22: 9 | G22: Calibration Standard | H22: 1 | I22: 1 | J22: TP | K22: ug P/L | L22: 0.0294 | M22: 0.741 | N22: 10 | O22: TN | P22: ug N/L | Q22: 0.211 | R22: 2.54 | S22: 100
A23: 46085 | B23: 0.45006944 | C23: OM_3-4-2026_10-18-36AM.OMN | D23: cal std 5 | F23: 11 | G23: Calibration Standard | H23: 1 | I23: 1 | J23: TP | K23: ug P/L | L23: 0.0275 | M23: 0.728 | N23: 5 | O23: TN | P23: ug N/L | Q23: 0.155 | R23: 1.8 | S23: 50
A24: 46085 | B24: 0.45096065 | C24: OM_3-4-2026_10-18-36AM.OMN | D24: cal std 5 | F24: 11 | G24: Calibration Standard | H24: 1 | I24: 1 | J24: TP | K24: ug P/L | L24: 0.0261 | M24: 0.654 | N24: 5 | O24: TN | P24: ug N/L | Q24: 0.148 | R24: 1.71 | S24: 50
... A26: 46085 | B26: 0.45271991 | C26: OM_3-4-2026_10-18-36AM.OMN | D26: cal std 0 | F26: 13 | G26: Calibration Standard | H26: 1 | I26: 1 | J26: TP | K26: ug P/L | L26: 0.0182 | M26: 0.42 | N26: 0 | O26: TN | P26: ug N/L | Q26: 0.0745 | R26: 0.964 | S26: 0
A27: 46085 | B27: 0.45358796 | C27: OM_3-4-2026_10-18-36AM.OMN | D27: NO2 | F27: S1 | G27: Unknown | H27: 1 | I27: 1 | J27: TP | K27: ug P/L | L27: 0.138 | M27: 1.38 | N27: 31.1 | O27: TN | P27: ug N/L | Q27: 1.88 | R27: 20.3 | S27: 1500
A28: 46085 | B28: 0.45447917 | C28: OM_3-4-2026_10-18-36AM.OMN | D28: NO3 | F28: S2 | G28: Unknown | H28: 1 | I28: 1 | J28: TP | K28: ug P/L | L28: 0.141 | M28: 1.46 | N28: 34 | O28: TN | P28: ug N/L | Q28: 1.92 | R28: 20.4 | S28: 1510
A29: 46085 | B29: 0.45537037 | C29: OM_3-4-2026_10-18-36AM.OMN | D29: water | F29: S3 | G29: Unknown | H29: 1 | I29: 1 | J29: TP | K29: ug P/L | L29: 0.137 | M29: 1.37 | N29: 31 | O29: TN | P29: ug N/L | Q29: -0.00324 | R29: -0.0198 | S29: -85
A30: 46085 | B30: 0.45626157 | C30: OM_3-4-2026_10-18-36AM.OMN | D30: water blank | F30: 19 | G30: Unknown | H30: 1 | I30: 1 | J30: TP | K30: ug P/L | L30: 0.0189 | M30: 0.41 | N30: -1.72 | O30: TN | P30: ug N/L | Q30: 0.0752 | R30: 0.971 | S30: -7.82
A31: 46085 | B31: 0.45715278 | C31: OM_3-4-2026_10-18-36AM.OMN | D31: water blank | F31: 20 | G31: Unknown | H31: 1 | I31: 1 | J31: TP | K31: ug P/L | L31: 0.0196 | M31: 0.395 | N31: -2.22 | O31: TN | P31: ug N/L | Q31: 0.0883 | R31: 1.12 | S31: 3.67
A32: 46085 | B32: 0.45804398 | C32: OM_3-4-2026_10-18-36AM.OMN | D32: water blank | F32: 21 | G32: Unknown | H32: 1 | I32: 1 | J32: TP | K32: ug P/L | L32: 0.0174 | M32: 0.415 | N32: -1.56 | O32: TN | P32: ug N/L | Q32: 0.0736 | R32: 0.978 | S32: -7.26
A33: 46085 | B33: 0.45893519 | C33: OM_3-4-2026_10-18-36AM.OMN | D33: water blank | F33: 22 | G33: Unknown | H33: 1 | I33: 1 | J33: TP | K33: ug P/L | L33: 0.0212 | M33: 0.486 | N33: 0.811 | O33: TN | P33: ug N/L | Q33: 0.0751 | R33: 0.944 | S33: -9.93
A34: 46085 | B34: 0.45981481 | C34: OM_3-4-2026_10-18-36AM.OMN | D34: water blank | F34: 23 | G34: Unknown | H34: 1 | I34: 1 | J34: TP | K34: ug P/L | L34: 0.0202 | M34: 0.446 | N34: -0.533 | O34: TN | P34: ug N/L | Q34: 0.0798 | R34: 1.12 | S34: 3.8
A35: 46085 | B35: 0.46069444 | C35: OM_3-4-2026_10-18-36AM.OMN | D35: digest check | F35: 24 | G35: Unknown | H35: 1 | I35: 1 | J35: TP | K35: ug P/L | L35: 0.0856 | M35: 1.64 | N35: 40.4 | O35: TN | P35: ug N/L | Q35: 0.564 | R35: 6.09 | S35: 391
A36: 46085 | B36: 0.46158565 | C36: OM_3-4-2026_10-18-36AM.OMN | D36: digest check | F36: 25 | G36: Unknown | H36: 1 | I36: 1 | J36: TP | K36: ug P/L | L36: 0.0858 | M36: 1.59 | N36: 38.5 | O36: TN | P36: ug N/L | Q36: 0.586 | R36: 6.32 | S36: 409
A37: 46085 | B37: 0.46246528 | C37: OM_3-4-2026_10-18-36AM.OMN | D37: digest check | F37: 26 | G37: Unknown | H37: 1 | I37: 1 | J37: TP | K37: ug P/L | L37: 0.0854 | M37: 1.62 | N37: 39.5 | O37: TN | P37: ug N/L | Q37: 0.538 | R37: 5.85 | S37: 372
A38: 46085 | B38: 0.46334491 | C38: OM_3-4-2026_10-18-36AM.OMN | D38: digest check | F38: 27 | G38: Unknown | H38: 1 | I38: 1 | J38: TP | K38: ug P/L | L38: 0.0824 | M38: 1.56 | N38: 37.5 | O38: TN | P38: ug N/L | Q38: 0.557 | R38: 6.13 | S38: 394
A39: 46085 | B39: 0.46422454 | C39: OM_3-4-2026_10-18-36AM.OMN | D39: digest check | F39: 28 | G39: Unknown | H39: 1 | I39: 1 | J39: TP | K39: ug P/L | L39: 0.0845 | M39: 1.67 | N39: 41.4 | O39: TN | P39: ug N/L | Q39: 0.599 | R39: 6.45 | S39: 418
A40: 46085 | B40: 0.46510417 | C40: OM_3-4-2026_10-18-36AM.OMN | D40: spk blank | F40: 29 | G40: Unknown | H40: 1 | I40: 1 | J40: TP | K40: ug P/L | L40: 0.0721 | M40: 1.05 | N40: 20 | O40: TN | P40: ug N/L | Q40: 0.392 | R40: 4.3 | S40: 251
A41: 46085 | B41: 0.4659838 | C41: OM_3-4-2026_10-18-36AM.OMN | D41: spk blank | F41: 30 | G41: Unknown | H41: 1 | I41: 1 | J41: TP | K41: ug P/L | L41: 0.0531 | M41: 0.93 | N41: 15.8 | O41: TN | P41: ug N/L | Q41: 0.422 | R41: 4.66 | S41: 279
... A44: 46085 | B44: 0.46866898 | C44: OM_3-4-2026_10-18-36AM.OMN | D44: spk blank | F44: 33 | G44: Unknown | H44: 1 | I44: 1 | J44: TP | K44: ug P/L | L44: 0.0571 | M44: 0.997 | N44: 18.1 | O44: TN | P44: ug N/L | Q44: 0.382 | R44: 4.23 | S44: 246
...

Sheet Calibration-S40 to end
A1: Output from R:
A3: TN | M3: TP
A5: Call: | M5: Call:
A6: lm(formula = x ~ poly(y, 2, raw = TRUE), data = data1, weights = 1/x) | M6: lm(formula = x ~ poly(y, 2, raw = TRUE), data = data1, weights = 1/x)
A8: Weighted Residuals: | M8: Weighted Residuals:
A9: 1 2 3 4 5 6 7 | M9: 1 2 3 4 5 6
A10: 0.19585 -0.42934 -0.64886 2.07653 0.19881 -1.13711 0.02949 | H10: Coefficients extracted: | M10: 0.097423 -0.189299 0.005276 0.068237 0.125252 -0.026673 | T10: Coefficients extracted:
H11: a | I11: -0.8422 | T11: a | U11: -0.3627
A12: Coefficients: | H12: b | I12: 79.2321 | M12: Coefficients: | T12: b | U12: 31.3525
A13: Estimate Std. Error t value Pr(>|t|) | H13: c | I13: -99.6559 | M13: Estimate Std. Error t value Pr(>|t|) | T13: c | U13: -14.1767
A14: (Intercept) -99.6559 4.5934 -21.695 2.67e-05 *** | M14: (Intercept) -14.1767 0.3618 -39.184 3.66e-05 ***
A15: poly(y, 2, raw = TRUE)1 79.2321 3.6608 21.643 2.70e-05 *** | M15: poly(y, 2, raw = TRUE)1 31.3525 0.7803 40.180 3.39e-05 ***
A16: poly(y, 2, raw = TRUE)2 -0.8422 0.1476 -5.704 0.00467 ** | M16: poly(y, 2, raw = TRUE)2 -0.3627 0.1590 -2.282 0.107
A17: --- | M17: ---
A18: Signif. codes: 0 ‘***’ 0.001 ‘**’ 0.01 ‘*’ 0.05 ‘.’ 0.1 ‘ ’ 1 | M18: Signif. codes: 0 ‘***’ 0.001 ‘**’ 0.01 ‘*’ 0.05 ‘.’ 0.1 ‘ ’ 1
A20: Residual standard error: 1.254 on 4 degrees of freedom | M20: Residual standard error: 0.1488 on 3 degrees of freedom
A21: Multiple R-squared: 0.9981, Adjusted R-squared: 0.9972 | M21: Multiple R-squared: 0.9998, Adjusted R-squared: 0.9997
A22: F-statistic: 1074 on 2 and 4 DF, p-value: 3.455e-06 | M22: F-statistic: 7315 on 2 and 3 DF, p-value: 2.935e-06
